[ 2023-10-15 21:59:51,719 ] 12 root - INFO - In App.py
[ 2023-10-15 21:59:51,720 ] 15 root - INFO - Showing Index page
[ 2023-10-15 21:59:51,738 ] 96 werkzeug - INFO - [31m[1mWARNING: This is a development server. Do not use it in a production deployment. Use a production WSGI server instead.[0m
 * Running on http://127.0.0.1:5000
[ 2023-10-15 21:59:51,738 ] 96 werkzeug - INFO - [33mPress CTRL+C to quit[0m
[ 2023-10-15 22:00:01,321 ] 96 werkzeug - INFO - 127.0.0.1 - - [15/Oct/2023 22:00:01] "GET / HTTP/1.1" 200 -
[ 2023-10-15 22:00:01,411 ] 96 werkzeug - INFO - 127.0.0.1 - - [15/Oct/2023 22:00:01] "[33mGET /favicon.ico HTTP/1.1[0m" 404 -
[ 2023-10-15 22:00:46,883 ] 23 root - INFO - Submit command recieved
[ 2023-10-15 22:00:47,175 ] 43 root - INFO - recieved values [51, 'Private', 108438, 'Masters', 14, 'Married-civ-spouse', 'Prof-specialty', 'Husband', 'select from here', 'Male', 0, 0, 47, 'United-States']
[ 2023-10-15 22:00:47,175 ] 16 root - INFO - In Predict py importing models
[ 2023-10-15 22:00:47,319 ] 24 root - INFO - Data Transoformation
[ 2023-10-15 22:00:47,320 ] 26 root - INFO - Predicting Results
[ 2023-10-15 22:00:47,325 ] 39 root - INFO - Error occured in python script name [F:\AdultCensusIncomePredictionEndtoEndProject\src\components\predict.py] line number [27] error message[Found unknown categories ['select from here'] in column 5 during transform]
[ 2023-10-15 22:00:47,325 ] 825 app - ERROR - Exception on /submit [POST]
Traceback (most recent call last):
  File "F:\AdultCensusIncomePredictionEndtoEndProject\src\components\predict.py", line 27, in prediction
    data = preprocessor.transform(data)
  File "F:\AdultCensusIncomePredictionEndtoEndProject\venv\lib\site-packages\sklearn\utils\_set_output.py", line 157, in wrapped
    data_to_wrap = f(self, X, *args, **kwargs)
  File "F:\AdultCensusIncomePredictionEndtoEndProject\venv\lib\site-packages\sklearn\compose\_column_transformer.py", line 827, in transform
    Xs = self._fit_transform(
  File "F:\AdultCensusIncomePredictionEndtoEndProject\venv\lib\site-packages\sklearn\compose\_column_transformer.py", line 681, in _fit_transform
    return Parallel(n_jobs=self.n_jobs)(
  File "F:\AdultCensusIncomePredictionEndtoEndProject\venv\lib\site-packages\sklearn\utils\parallel.py", line 65, in __call__
    return super().__call__(iterable_with_config)
  File "F:\AdultCensusIncomePredictionEndtoEndProject\venv\lib\site-packages\joblib\parallel.py", line 1863, in __call__
    return output if self.return_generator else list(output)
  File "F:\AdultCensusIncomePredictionEndtoEndProject\venv\lib\site-packages\joblib\parallel.py", line 1792, in _get_sequential_output
    res = func(*args, **kwargs)
  File "F:\AdultCensusIncomePredictionEndtoEndProject\venv\lib\site-packages\sklearn\utils\parallel.py", line 127, in __call__
    return self.function(*args, **kwargs)
  File "F:\AdultCensusIncomePredictionEndtoEndProject\venv\lib\site-packages\sklearn\pipeline.py", line 940, in _transform_one
    res = transformer.transform(X)
  File "F:\AdultCensusIncomePredictionEndtoEndProject\venv\lib\site-packages\sklearn\pipeline.py", line 696, in transform
    Xt = transform.transform(Xt)
  File "F:\AdultCensusIncomePredictionEndtoEndProject\venv\lib\site-packages\sklearn\utils\_set_output.py", line 157, in wrapped
    data_to_wrap = f(self, X, *args, **kwargs)
  File "F:\AdultCensusIncomePredictionEndtoEndProject\venv\lib\site-packages\sklearn\preprocessing\_encoders.py", line 1027, in transform
    X_int, X_mask = self._transform(
  File "F:\AdultCensusIncomePredictionEndtoEndProject\venv\lib\site-packages\sklearn\preprocessing\_encoders.py", line 200, in _transform
    raise ValueError(msg)
ValueError: Found unknown categories ['select from here'] in column 5 during transform

During handling of the above exception, another exception occurred:

Traceback (most recent call last):
  File "F:\AdultCensusIncomePredictionEndtoEndProject\venv\lib\site-packages\flask\app.py", line 1455, in wsgi_app
    response = self.full_dispatch_request()
  File "F:\AdultCensusIncomePredictionEndtoEndProject\venv\lib\site-packages\flask\app.py", line 869, in full_dispatch_request
    rv = self.handle_user_exception(e)
  File "F:\AdultCensusIncomePredictionEndtoEndProject\venv\lib\site-packages\flask\app.py", line 867, in full_dispatch_request
    rv = self.dispatch_request()
  File "F:\AdultCensusIncomePredictionEndtoEndProject\venv\lib\site-packages\flask\app.py", line 852, in dispatch_request
    return self.ensure_sync(self.view_functions[rule.endpoint])(**view_args)
  File "app.py", line 44, in submit
    result = prediction(inputs)
  File "F:\AdultCensusIncomePredictionEndtoEndProject\src\components\predict.py", line 40, in prediction
    raise CustomException(e,sys)
src.exception.CustomException: Error occured in python script name [F:\AdultCensusIncomePredictionEndtoEndProject\src\components\predict.py] line number [27] error message[Found unknown categories ['select from here'] in column 5 during transform]
[ 2023-10-15 22:00:47,329 ] 96 werkzeug - INFO - 127.0.0.1 - - [15/Oct/2023 22:00:47] "[35m[1mPOST /submit HTTP/1.1[0m" 500 -
